exception calling callback for <Future at 0x2b1ba3e2e48 state=finished returned list>
Traceback (most recent call last):
  File "c:\python\python36\Lib\concurrent\futures\_base.py", line 324, in _invoke_callbacks
    callback(self)
  File "c:\python\python36\Lib\asyncio\futures.py", line 417, in _call_set_state
    dest_loop.call_soon_threadsafe(_set_state, destination, source)
  File "c:\python\python36\Lib\asyncio\base_events.py", line 637, in call_soon_threadsafe
    self._check_closed()
  File "c:\python\python36\Lib\asyncio\base_events.py", line 377, in _check_closed
    raise RuntimeError('Event loop is closed')
RuntimeError: Event loop is closed
Task was destroyed but it is pending!
task: <Task pending coro=<TCPConnector._resolve_host() done, defined at c:\users\carolina\documents\rasa_ccat_bot\rasaenv\lib\site-packages\aiohttp\connector.py:773> wait_for=<Future pending cb=[_chain_future.<locals>._call_check_cancel() at c:\python\python36\Lib\asyncio\futures.py:403, <TaskWakeupMethWrapper object at 0x000002B1BA443738>()]> cb=[shield.<locals>._done_callback() at c:\python\python36\Lib\asyncio\tasks.py:688]>
